Workbook

Sheet REKAP
A1: REKAP ESTIMASI ZAMRUD | M1: Ket : | O1: Diisi
A2: Smt. 2 Tahun Ajaran 2026 - 2027
J3: (Mohon diisi)
A4: NO | B4: Produk | C4: Exp LKS | D4: Exp PG | E4: Nominal LKS | F4: Nominal PG | H4: Nama | I4: :
A5: 1 | B5: AKM & P5 | C5: ='AKM & P5'!H23 -> 0 | D5: ='AKM & P5'!J23 -> 0 | E5: ='AKM & P5'!K23 -> 0 | F5: ='AKM & P5'!L23 -> 0 | H5: Area | I5: :
A6: 2 | B6: SD | C6: =sd!F94+sd!R18 -> 0 | D6: =sd!I94+sd!U18 -> 0 | E6: =sd!J94+sd!V18 -> 0 | F6: =sd!K94+sd!W18 -> 0 | H6: Tanggal | I6: :
A7: 3 | B7: SMP | C7: =+SMP!F75 -> 0 | D7: =+SMP!I75 -> 0 | E7: =+SMP!J75 -> 0 | F7: =+SMP!K75 -> 0
A8: 4 | B8: SMA_SMK | C8: =+SMA!F100+SMA!R23 -> 0 | D8: =SMA!I100+SMA!U23 -> 0 | E8: =+SMA!J100+SMA!V23 -> 0 | F8: =+SMA!K100+SMA!W23 -> 0
A9: 5 | B9: SMK | C9: =+SMK!G29 -> 0 | D9: =+SMK!I29 -> 0 | E9: =+SMK!J29 -> 0 | F9: =+SMK!K29 -> 0
A10: 6 | B10: Produktif | C10: =PROD!G72 -> 0 | D10: =PROD!I72 -> 0 | E10: =PROD!J72 -> 0 | F10: =PROD!K72 -> 0
A11: 7 | B11: Madrasah | C11: =MADRASAH!G70 -> 0 | D11: =MADRASAH!J70 -> 0 | E11: =MADRASAH!K70 -> 0 | F11: =MADRASAH!L70 -> 0
A12: 8 | B12: TK Akademik | C12: =TKA!G25 -> 0 | D12: =TKA!I25 -> 0 | E12: =TKA!J25 -> 0 | F12: =TKA!K25 -> 0
A13: 9 | B13: ASAJ UM | C13: ='ASAJ UM'!F39 -> 0 | D13: ='ASAJ UM'!H39 -> 0 | E13: ='ASAJ UM'!I39 -> 0 | F13: ='ASAJ UM'!J39 -> 0
A14: 10 | B14: JURNAL & TK | C14: ='jurnal & tk'!F27 -> 0 | E14: ='jurnal & tk'!G27 -> 0
C15: =SUM(C5:C14) -> 0 | D15: =SUM(D5:D14) -> 0 | E15: =SUM(E5:E14) -> 0 | F15: =SUM(F5:F14) -> 0
B16: Total Pengambilan | C16: Eksemplar | D16: =C15+D15 -> 0 | E16: Nominal | F16: =E15+F15 -> 0
D17: Potongan | F17: =F16*E17 -> 0
D18: Pembelian Netto | F18: =F16-F17 -> 0
D19: Biaya Kirim
D20: TOTAL | F20: =F18+F19 -> 0
D21: PEMBAYARAN
D22: SALDO | F22: =F20-F21 -> 0
A24: CATATAN :
A25: 1 | B25: Petunjuk pengisian :
B26: a. Silahkan diisi pada sheet selain REKAP dan Base sesuai yang dibutuhkan
B27: b. Jangan mengganti apapun selain order pada colom yang telah disediakan data di atas jika ada penambahan mohon dibuat tersendiri.
B28: c. Pada sheet REKAP mohon diisi nama area dan tanggal
A29: 2 | B29: Estimasi Mohon Segera di Masukkan demi ketersediaan stok dikemudian hari
A30: 3 | B30: Pengisian PG adalah untuk yang beli saja selain sample yang didapatkan. PG SD setingkat 40: 1 selain SD 100: 1
A31: 4 | B31: RETUR Maximal 5% dari total pengambilan (Jika melebihi akan kena pinalti 70%)

Sheet AKM & P5
A1: ESTIMASI ZAMRUD AKM - AKMI - P5
A2: NAMA : | B2: =REKAP!$J$4 -> 0
A4: No | B4: Jenjang | C4: Jenis | D4: Bidang Studi | E4: Kls | F4: Hal | G4: Harga | H4: ORDER LKS | I4: Harga PG | J4: PG BELI
A5: 1 | B5: SD | C5: AKM | D5: SD | F5: 176 | G5: 17800 | I5: 29800 | K5: =H5*G5 -> 0 | L5: =J5*I5 -> 0
A6: 2 | B6: SMP | D6: SMP | F6: 176 | G6: 17800 | I6: 28000 | K6: =H6*G6 -> 0 | L6: =J6*I6 -> 0
A7: 3 | B7: SMA | D7: SMA-SMK | F7: 240 | G7: 23800 | I7: 36500 | K7: =H7*G7 -> 0 | L7: =J7*I7 -> 0
A8: 4 | B8: SD | C8: AKMI | D8: MI | F8: 144 | G8: 15300 | I8: 19500 | K8: =H8*G8 -> 0 | L8: =J8*I8 -> 0
A9: 5 | B9: SMP | D9: MTS | F9: 144 | G9: 15300 | I9: 24500 | K9: =H9*G9 -> 0 | L9: =J9*I9 -> 0
A10: 6 | B10: SMA | D10: MAK | F10: 144 | G10: 15300 | I10: 23000 | K10: =H10*G10 -> 0 | L10: =J10*I10 -> 0
A11: 7 | C11: SD | D11: P5 SD | E11: 1 | F11: 128 | G11: 13600 | K11: =H11*G11 -> 0 | L11: =J11*I11 -> 0
A12: 8 | D12: P5 SD | E12: 2 | F12: 128 | G12: 13600 | K12: =H12*G12 -> 0 | L12: =J12*I12 -> 0
A13: 9 | D13: P5 SD | E13: 3 | F13: 128 | G13: 13600 | K13: =H13*G13 -> 0 | L13: =J13*I13 -> 0
A14: 10 | D14: P5 SD | E14: 4 | F14: 128 | G14: 13600 | K14: =H14*G14 -> 0 | L14: =J14*I14 -> 0
A15: 11 | D15: P5 SD | E15: 5 | F15: 128 | G15: 13600 | K15: =H15*G15 -> 0 | L15: =J15*I15 -> 0
A16: 12 | D16: P5 SD | E16: 6 | F16: 128 | G16: 13600 | K16: =H16*G16 -> 0 | L16: =J16*I16 -> 0
A17: 13 | C17: SMP | D17: P5 SMP | E17: 7 | F17: 128 | G17: 13600 | K17: =H17*G17 -> 0 | L17: =J17*I17 -> 0
A18: 14 | D18: P5 SMP | E18: 8 | F18: 128 | G18: 13600 | K18: =H18*G18 -> 0 | L18: =J18*I18 -> 0
A19: 15 | D19: P5 SMP | E19: 9 | F19: 128 | G19: 13600 | K19: =H19*G19 -> 0 | L19: =J19*I19 -> 0
A20: 16 | C20: SMA | D20: P5 SMA | E20: 10 | F20: 128 | G20: 13600 | K20: =H20*G20 -> 0 | L20: =J20*I20 -> 0
A21: 17 | D21: P5 SMA | E21: 11 | F21: 128 | G21: 13600 | K21: =H21*G21 -> 0 | L21: =J21*I21 -> 0
A22: 18 | D22: P5 SMA | E22: 12 | F22: 128 | G22: 13600 | K22: =H22*G22 -> 0 | L22: =J22*I22 -> 0
H23: =SUM(H5:H22) -> 0 | J23: =SUM(J5:J10) -> 0 | K23: =SUM(K5:K22) -> 0 | L23: =SUM(L5:L10) -> 0
B25: Nama | C25: : | D25: =REKAP!J4 -> 0
B26: Area | C26: : | D26: =REKAP!J5 -> 0
B27: Tanggal | C27: : | D27: =REKAP!J6 -> 0
B33: ( ………………………………………………………..)
B34: Tanda tangan dan nama Terang

Sheet sd
A1: DAFTAR ESTIMASI ZAMRUD SD MERDEKA
A2: =REKAP!A2 -> Smt. 2 Tahun Ajaran 2026 - 2027
A3: NAMA : | B3: =REKAP!$J$4 -> 0
A4: No | B4: Bidang Studi Kur. Merdeka | C4: Kls | D4: Hal | E4: Harga | F4: ORDER LKS | G4: Harga PG | H4: Hal PG | I4: PG Beli | M4: No | N4: KUR. Mer SD Terpadu | O4: Kls | P4: Hal | Q4: Harga | R4: ORDER LKS | S4: Harga PG | T4: Hal PG | U4: PG Beli
A6: 1 | B6: Pkn | C6: 1 | D6: 112 | E6: 4350 | G6: 9000 | H6: 128 | J6: =F6*E6 -> 0 | K6: =I6*G6 -> 0 | M6: 1 | N6: SD TERPADU | O6: 1 | P6: 224 | Q6: 9150 | S6: 15000 | T6: 368 | V6: =R6*Q6 -> 0 | W6: =U6*S6 -> 0
A7: 2 | B7: Pkn | C7: 2 | D7: 112 | E7: 4350 | G7: 9000 | H7: 128 | J7: =F7*E7 -> 0 | K7: =I7*G7 -> 0 | M7: 2 | N7: SD TERPADU | O7: 2 | P7: 224 | Q7: 9150 | S7: 15000 | T7: 384 | V7: =R7*Q7 -> 0 | W7: =U7*S7 -> 0
A8: 3 | B8: Pkn | C8: 3 | D8: 112 | E8: 4350 | G8: 9000 | H8: 128 | J8: =F8*E8 -> 0 | K8: =I8*G8 -> 0 | M8: 3 | N8: SD TERPADU | O8: 3 | P8: 256 | Q8: 10500 | S8: 15000 | T8: 448 | V8: =R8*Q8 -> 0 | W8: =U8*S8 -> 0
A9: 4 | B9: Pkn | C9: 4 | D9: 112 | E9: 4350 | G9: 9000 | H9: 144 | J9: =F9*E9 -> 0 | K9: =I9*G9 -> 0 | M9: 4 | N9: SD TERPADU | O9: 4 | P9: 256 | Q9: 10500 | S9: 15000 | T9: 480 | V9: =R9*Q9 -> 0 | W9: =U9*S9 -> 0
A10: 5 | B10: Pkn | C10: 5 | D10: 112 | E10: 4350 | G10: 9000 | H10: 128 | J10: =F10*E10 -> 0 | K10: =I10*G10 -> 0 | M10: 5 | N10: SD TERPADU | O10: 5 | P10: 256 | Q10: 10500 | S10: 15000 | T10: 480 | V10: =R10*Q10 -> 0 | W10: =U10*S10 -> 0
A11: 6 | B11: Pkn | C11: 6 | D11: 112 | E11: 4350 | G11: 9000 | H11: 144 | J11: =F11*E11 -> 0 | K11: =I11*G11 -> 0 | M11: 6 | N11: SD TERPADU | O11: 6 | P11: 256 | Q11: 10500 | S11: 15000 | T11: 448 | V11: =R11*Q11 -> 0 | W11: =U11*S11 -> 0
A12: 7 | B12: Bahasa Indonesia | C12: 1 | D12: 112 | E12: 4350 | G12: 9000 | H12: 128 | J12: =F12*E12 -> 0 | K12: =I12*G12 -> 0 | M12: 7 | N12: Seni Terpadu | O12: 1 | P12: 112 | Q12: 4350 | S12: 9000 | T12: 128 | V12: =R12*Q12 -> 0 | W12: =U12*S12 -> 0
A13: 8 | B13: Bahasa Indonesia | C13: 2 | D13: 112 | E13: 4350 | G13: 9000 | H13: 144 | J13: =F13*E13 -> 0 | K13: =I13*G13 -> 0 | M13: 8 | N13: Seni Terpadu | O13: 2 | P13: 112 | Q13: 4350 | S13: 9000 | T13: 144 | V13: =R13*Q13 -> 0 | W13: =U13*S13 -> 0
A14: 9 | B14: Bahasa Indonesia | C14: 3 | D14: 112 | E14: 4350 | G14: 9000 | H14: 160 | J14: =F14*E14 -> 0 | K14: =I14*G14 -> 0 | M14: 9 | N14: Seni Terpadu | O14: 3 | P14: 112 | Q14: 4350 | S14: 9000 | T14: 144 | V14: =R14*Q14 -> 0 | W14: =U14*S14 -> 0
A15: 10 | B15: Bahasa Indonesia | C15: 4 | D15: 112 | E15: 4350 | G15: 9000 | H15: 144 | J15: =F15*E15 -> 0 | K15: =I15*G15 -> 0 | M15: 10 | N15: Seni Terpadu | O15: 4 | P15: 112 | Q15: 4350 | S15: 9000 | T15: 144 | V15: =R15*Q15 -> 0 | W15: =U15*S15 -> 0
A16: 11 | B16: Bahasa Indonesia | C16: 5 | D16: 112 | E16: 4350 | G16: 9000 | H16: 144 | J16: =F16*E16 -> 0 | K16: =I16*G16 -> 0 | M16: 11 | N16: Seni Terpadu | O16: 5 | P16: 112 | Q16: 4350 | S16: 9000 | T16: 144 | V16: =R16*Q16 -> 0 | W16: =U16*S16 -> 0
A17: 12 | B17: Bahasa Indonesia | C17: 6 | D17: 112 | E17: 4350 | G17: 9000 | H17: 144 | J17: =F17*E17 -> 0 | K17: =I17*G17 -> 0 | M17: 12 | N17: Seni Terpadu | O17: 6 | P17: 112 | Q17: 4350 | S17: 9000 | T17: 160 | V17: =R17*Q17 -> 0 | W17: =U17*S17 -> 0
A18: 13 | B18: Matematika | C18: 1 | D18: 112 | E18: 4350 | G18: 9000 | H18: 144 | J18: =F18*E18 -> 0 | K18: =I18*G18 -> 0 | R18: =SUM(R6:R17) -> 0 | U18: =SUM(U6:U17) -> 0 | V18: =SUM(V6:V17) -> 0 | W18: =SUM(W6:W17) -> 0
A19: 14 | B19: Matematika | C19: 2 | D19: 112 | E19: 4350 | G19: 9000 | H19: 144 | J19: =F19*E19 -> 0 | K19: =I19*G19 -> 0
A20: 15 | B20: Matematika | C20: 3 | D20: 112 | E20: 4350 | G20: 9000 | H20: 128 | J20: =F20*E20 -> 0 | K20: =I20*G20 -> 0
A21: 16 | B21: Matematika | C21: 4 | D21: 112 | E21: 4350 | G21: 9000 | H21: 176 | J21: =F21*E21 -> 0 | K21: =I21*G21 -> 0
A22: 17 | B22: Matematika | C22: 5 | D22: 112 | E22: 4350 | G22: 9000 | H22: 192 | J22: =F22*E22 -> 0 | K22: =I22*G22 -> 0
A23: 18 | B23: Matematika | C23: 6 | D23: 112 | E23: 4350 | G23: 9000 | H23: 176 | J23: =F23*E23 -> 0 | K23: =I23*G23 -> 0
A24: 19 | B24: IPAS Semester 1 | C24: 3 | D24: 112 | H24: 160 | J24: =F24*E24 -> 0 | K24: =I24*G24 -> 0
A25: 20 | B25: IPAS Semester 2 | C25: 3 | D25: 112 | E25: 4350 | G25: 9000 | H25: 160 | J25: =F25*E25 -> 0 | K25: =I25*G25 -> 0
A26: 21 | B26: IPAS Semester 1 | C26: 4 | D26: 112 | H26: 144 | J26: =F26*E26 -> 0 | K26: =I26*G26 -> 0
A27: 22 | B27: IPAS Semester 2 | C27: 4 | D27: 112 | E27: 4350 | G27: 9000 | H27: 160 | J27: =F27*E27 -> 0 | K27: =I27*G27 -> 0
A28: 23 | B28: IPAS Semester 1 | C28: 5 | D28: 112 | H28: 144 | J28: =F28*E28 -> 0 | K28: =I28*G28 -> 0
A29: 24 | B29: IPAS Semester 2 | C29: 5 | D29: 112 | E29: 4350 | G29: 9000 | H29: 144 | J29: =F29*E29 -> 0 | K29: =I29*G29 -> 0
A30: 25 | B30: IPAS Semester 1 | C30: 6 | D30: 112 | H30: 144 | J30: =F30*E30 -> 0 | K30: =I30*G30 -> 0
A31: 26 | B31: IPAS Semester 2 | C31: 6 | D31: 112 | E31: 4350 | G31: 9000 | H31: 144 | J31: =F31*E31 -> 0 | K31: =I31*G31 -> 0
A32: 27 | B32: Bahasa Inggris | C32: 1 | D32: 80 | E32: 3650 | G32: 9000 | H32: 112 | J32: =F32*E32 -> 0 | K32: =I32*G32 -> 0
A33: 28 | B33: Bahasa Inggris | C33: 2 | D33: 64 | E33: 3350 | G33: 9000 | H33: 96 | J33: =F33*E33 -> 0 | K33: =I33*G33 -> 0
A34: 29 | B34: Bahasa Inggris | C34: 3 | D34: 64 | E34: 3350 | G34: 9000 | H34: 96 | J34: =F34*E34 -> 0 | K34: =I34*G34 -> 0
A35: 30 | B35: Bahasa Inggris | C35: 4 | D35: 64 | E35: 3350 | G35: 9000 | H35: 96 | J35: =F35*E35 -> 0 | K35: =I35*G35 -> 0
A36: 31 | B36: Bahasa Inggris | C36: 5 | D36: 64 | E36: 3350 | G36: 9000 | H36: 96 | J36: =F36*E36 -> 0 | K36: =I36*G36 -> 0
A37: 32 | B37: Bahasa Inggris | C37: 6 | D37: 64 | E37: 3350 | G37: 9000 | H37: 112 | J37: =F37*E37 -> 0 | K37: =I37*G37 -> 0
A38: 33 | B38: PJOK | C38: 1 | D38: 64 | E38: 3350 | G38: 9000 | H38: 96 | J38: =F38*E38 -> 0 | K38: =I38*G38 -> 0
A39: 34 | B39: PJOK | C39: 2 | D39: 64 | E39: 3350 | G39: 9000 | H39: 96 | J39: =F39*E39 -> 0 | K39: =I39*G39 -> 0
A40: 35 | B40: PJOK | C40: 3 | D40: 64 | E40: 3350 | G40: 9000 | H40: 96 | J40: =F40*E40 -> 0 | K40: =I40*G40 -> 0
A41: 36 | B41: PJOK | C41: 4 | D41: 64 | E41: 3350 | G41: 9000 | H41: 96 | J41: =F41*E41 -> 0 | K41: =I41*G41 -> 0
...

Sheet SMP
A1: DAFTAR LKS ZAMRUD SMP
A2: =REKAP!A2 -> Smt. 2 Tahun Ajaran 2026 - 2027
A3: NAMA : | B3: =REKAP!$J$4 -> 0
A4: No | B4: Bidang Studi Kur Merdeka | C4: Kls | D4: Hal | E4: Harga | F4: ORDER LKS | G4: Harga PG | H4: Hal PG | I4: PG Beli
A6: 1 | B6: PPkn | C6: 7 | D6: 64 | E6: 3350 | G6: 8000 | H6: 96 | J6: =F6*E6 -> 0 | K6: =I6*G6 -> 0
A7: 2 | B7: PPkn | C7: 8 | D7: 64 | E7: 3350 | G7: 8000 | H7: 112 | J7: =F7*E7 -> 0 | K7: =I7*G7 -> 0
A8: 3 | B8: PPkn | C8: 9 | D8: 64 | E8: 3350 | G8: 8000 | H8: 112 | J8: =F8*E8 -> 0 | K8: =I8*G8 -> 0
A9: 4 | B9: Bahasa Indonesia | C9: 7 | D9: 64 | E9: 3350 | G9: 8000 | H9: 96 | J9: =F9*E9 -> 0 | K9: =I9*G9 -> 0
A10: 5 | B10: Bahasa Indonesia | C10: 8 | D10: 64 | E10: 3350 | G10: 8000 | H10: 96 | J10: =F10*E10 -> 0 | K10: =I10*G10 -> 0
A11: 6 | B11: Bahasa Indonesia | C11: 9 | D11: 64 | E11: 3350 | G11: 8000 | H11: 96 | J11: =F11*E11 -> 0 | K11: =I11*G11 -> 0
A12: 7 | B12: Matematika | C12: 7 | D12: 80 | E12: 3650 | G12: 8000 | H12: 128 | J12: =F12*E12 -> 0 | K12: =I12*G12 -> 0
A13: 8 | B13: Matematika | C13: 8 | D13: 80 | E13: 3650 | G13: 8000 | H13: 144 | J13: =F13*E13 -> 0 | K13: =I13*G13 -> 0
A14: 9 | B14: Matematika | C14: 9 | D14: 80 | E14: 3650 | G14: 8000 | H14: 128 | J14: =F14*E14 -> 0 | K14: =I14*G14 -> 0
A15: 10 | B15: IPA Terpadu | C15: 7 | D15: 128 | E15: 5150 | G15: 8000 | H15: 176 | J15: =F15*E15 -> 0 | K15: =I15*G15 -> 0
A16: 11 | B16: IPA Terpadu | C16: 8 | D16: 128 | E16: 5150 | G16: 8000 | H16: 176 | J16: =F16*E16 -> 0 | K16: =I16*G16 -> 0
A17: 12 | B17: IPA Terpadu | C17: 9 | D17: 128 | E17: 5150 | G17: 8000 | H17: 192 | J17: =F17*E17 -> 0 | K17: =I17*G17 -> 0
... A71: 66 | B71: Prakarya Terpadu | C71: 9 | D71: 80 | E71: 3650 | G71: 8000 | H71: 144 | J71: =F71*E71 -> 0 | K71: =I71*G71 -> 0
A72: 67 | B72: KODING | C72: 7 | D72: 64 | E72: 3350 | G72: 8000
A73: 68 | B73: KODING | C73: 8 | D73: 64 | E73: 3350 | G73: 8000 | J73: =F73*E73 -> 0 | K73: =I73*G73 -> 0
A74: 69 | B74: KODING | C74: 9 | D74: 64 | E74: 3350 | G74: 8000
F75: =SUM(F6:F74) -> 0 | I75: =SUM(I6:I74) -> 0 | J75: =SUM(J6:J73) -> 0 | K75: =SUM(K6:K73) -> 0

Sheet SMA
A1: DAFTAR LKS ZAMRUD SMA | M1: DAFTAR LKS ZAMRUD SMA
A2: =REKAP!A2 -> Smt. 2 Tahun Ajaran 2026 - 2027 | M2: =A2 -> Smt. 2 Tahun Ajaran 2026 - 2027
A3: NAMA : | B3: =REKAP!$J$4 -> 0
A4: No | B4: Bidang Studi Kur. Merdeka | C4: Kls | D4: Hal | E4: Harga | F4: ORDER LKS | G4: Harga PG | H4: Hal PG | I4: PG Beli | M4: No | N4: Bidang Studi Kur. Merdeka | O4: Kls | P4: Hal | Q4: Harga | R4: ORDER LKS | S4: Harga PG | T4: Hal PG | U4: PG Beli
A6: 1 | B6: PPkn [ SMA/SMK ] | C6: 10 | D6: 80 | E6: 3650 | G6: 8000 | H6: 112 | J6: =E6*F6 -> 0 | K6: =G6*I6 -> 0 | M6: 1 | N6: Pendidikan Pancasila SMA/SMK | O6: 12 | P6: 64 | Q6: 3350 | S6: 8000 | V6: =Q6*R6 -> 0 | W6: =Q6*U6 -> 0
A7: 2 | B7: PPkn [ SMA/SMK ] | C7: 11 | D7: 80 | E7: 3650 | G7: 8000 | H7: 112 | J7: =E7*F7 -> 0 | K7: =G7*I7 -> 0 | M7: 2 | N7: Bahasa Indonesia SMA/SMK | O7: 12 | P7: 64 | Q7: 3350 | S7: 8000 | V7: =Q7*R7 -> 0 | W7: =Q7*U7 -> 0
A8: 3 | B8: PPkn [ SMA/SMK ] 1 Tahun | C8: 12 | D8: 128 | E8: 5150 | G8: 8000 | H8: 208 | J8: =E8*F8 -> 0 | K8: =G8*I8 -> 0 | M8: 3 | N8: Matematika SMA/SMK | O8: 12 | P8: 80 | Q8: 3650 | S8: 8000 | V8: =Q8*R8 -> 0 | W8: =Q8*U8 -> 0
A9: 4 | B9: Bahasa Indonesia [ SMA/ SMK ] | C9: 10 | D9: 80 | E9: 3650 | G9: 8000 | H9: 112 | J9: =E9*F9 -> 0 | K9: =G9*I9 -> 0 | M9: 4 | N9: Matematika Tingkat Lanjut SMA | O9: 12 | P9: 80 | Q9: 3650 | S9: 8000 | V9: =Q9*R9 -> 0 | W9: =Q9*U9 -> 0
A10: 5 | B10: Bahasa Indonesia [ SMA/ SMK ] | C10: 11 | D10: 80 | E10: 3650 | G10: 8000 | H10: 112 | J10: =E10*F10 -> 0 | K10: =G10*I10 -> 0 | M10: 5 | N10: Fisika SMA | O10: 12 | P10: 64 | Q10: 3350 | S10: 8000 | V10: =Q10*R10 -> 0 | W10: =Q10*U10 -> 0
A11: 6 | B11: Bahasa Indonesia [ SMA/ SMK ] 1 Tahun | C11: 12 | D11: 128 | E11: 5150 | G11: 8000 | H11: 192 | J11: =E11*F11 -> 0 | K11: =G11*I11 -> 0 | M11: 6 | N11: Biologi SMA | O11: 12 | P11: 64 | Q11: 3350 | S11: 8000 | V11: =Q11*R11 -> 0 | W11: =Q11*U11 -> 0
A12: 7 | B12: Bahasa Indonesia tk. Lanjut [ SMA ] | C12: 11 | D12: 64 | E12: 3350 | G12: 8000 | J12: =E12*F12 -> 0 | K12: =G12*I12 -> 0 | M12: 7 | N12: Kimia SMA | O12: 12 | P12: 64 | Q12: 3350 | S12: 8000 | V12: =Q12*R12 -> 0 | W12: =Q12*U12 -> 0
A13: 8 | B13: Bahasa Indonesia tk. Lanjut [ SMA ] 1 Tahun | C13: 12 | D13: 128 | E13: 5150 | G13: 8000 | J13: =E13*F13 -> 0 | K13: =G13*I13 -> 0 | M13: 8 | N13: Sejarah SMA/SMK | O13: 12 | P13: 64 | Q13: 3350 | S13: 8000 | V13: =Q13*R13 -> 0 | W13: =Q13*U13 -> 0
A14: 9 | B14: Matematika [ SMA / SMK ] | C14: 10 | D14: 80 | E14: 3650 | G14: 8000 | H14: 128 | J14: =E14*F14 -> 0 | K14: =G14*I14 -> 0 | M14: 9 | N14: Sejarah TL SMA | O14: 12 | P14: 64 | Q14: 3350 | S14: 8000 | V14: =Q14*R14 -> 0 | W14: =Q14*U14 -> 0
A15: 10 | B15: Matematika [ SMA / SMK ] | C15: 11 | D15: 80 | E15: 3650 | G15: 8000 | H15: 144 | J15: =E15*F15 -> 0 | K15: =G15*I15 -> 0 | M15: 10 | N15: Ekonomi SMA | O15: 12 | P15: 64 | Q15: 3350 | S15: 8000 | V15: =Q15*R15 -> 0 | W15: =Q15*U15 -> 0
A16: 11 | B16: Matematika [ SMA / SMK ] 1 Tahun | C16: 12 | D16: 128 | E16: 5150 | G16: 8000 | H16: 192 | J16: =E16*F16 -> 0 | K16: =G16*I16 -> 0 | M16: 11 | N16: Geografi SMA | O16: 12 | P16: 64 | Q16: 3350 | S16: 8000 | V16: =Q16*R16 -> 0 | W16: =Q16*U16 -> 0
A17: 12 | B17: Matematika tk. Lanjut [ SMA ] | C17: 11 | D17: 80 | E17: 3650 | G17: 8000 | H17: 144 | J17: =E17*F17 -> 0 | K17: =G17*I17 -> 0 | M17: 12 | N17: Sosiologi SMA | O17: 12 | P17: 64 | Q17: 3350 | S17: 8000 | V17: =Q17*R17 -> 0 | W17: =Q17*U17 -> 0
A18: 13 | B18: Matematika tk. Lanjut [ SMA ] 1 Tahun | C18: 12 | D18: 128 | E18: 5150 | G18: 8000 | H18: 224 | J18: =E18*F18 -> 0 | K18: =G18*I18 -> 0 | M18: 13 | N18: Bahasa Inggris SMA/SMK | O18: 12 | P18: 64 | Q18: 3350 | S18: 8000 | V18: =Q18*R18 -> 0 | W18: =Q18*U18 -> 0
A19: 14 | B19: Fisika [ SMA ] | C19: 10 | D19: 80 | E19: 3650 | G19: 8000 | H19: 112 | J19: =E19*F19 -> 0 | K19: =G19*I19 -> 0 | M19: 14 | N19: B. Inggris Tingkat Lanjut SMA | O19: 12 | P19: 64 | Q19: 3350 | S19: 8000 | V19: =Q19*R19 -> 0 | W19: =Q19*U19 -> 0
A20: 15 | B20: Fisika [ SMA ] | C20: 11 | D20: 80 | E20: 3650 | G20: 8000 | H20: 128 | J20: =E20*F20 -> 0 | K20: =G20*I20 -> 0 | M20: 15 | N20: PJOK SMA/SMK | O20: 12 | P20: 64 | Q20: 3350 | S20: 8000 | V20: =Q20*R20 -> 0 | W20: =Q20*U20 -> 0
A21: 16 | B21: Fisika [ SMA ] 1 Tahun | C21: 12 | D21: 128 | E21: 5150 | G21: 8000 | H21: 224 | J21: =E21*F21 -> 0 | K21: =G21*I21 -> 0 | M21: 16 | N21: Pend. Agama Islam & BP SMA/SMK | O21: 12 | P21: 64 | Q21: 3350 | S21: 8000 | V21: =Q21*R21 -> 0 | W21: =Q21*U21 -> 0
A22: 17 | B22: Biologi [ SMA ] | C22: 10 | D22: 80 | E22: 3650 | G22: 8000 | H22: 112 | J22: =E22*F22 -> 0 | K22: =G22*I22 -> 0 | M22: 17 | N22: Informatika SMA | O22: 12 | P22: 64 | Q22: 3350 | S22: 8000 | V22: =Q22*R22 -> 0 | W22: =Q22*U22 -> 0
A23: 18 | B23: Biologi [ SMA ] | C23: 11 | D23: 80 | E23: 3650 | G23: 8000 | H23: 128 | J23: =E23*F23 -> 0 | K23: =G23*I23 -> 0 | R23: =SUM(R6:R22) -> 0 | U23: =SUM(U6:U22) -> 0 | V23: =SUM(V6:V22) -> 0 | W23: =SUM(W6:W22) -> 0
A24: 19 | B24: Biologi [ SMA ] 1 Tahun | C24: 12 | D24: 128 | E24: 5150 | G24: 8000 | H24: 176 | J24: =E24*F24 -> 0 | K24: =G24*I24 -> 0
A25: 20 | B25: Kimia [ SMA ] | C25: 10 | D25: 80 | E25: 3650 | G25: 8000 | H25: 112 | J25: =E25*F25 -> 0 | K25: =G25*I25 -> 0
A26: 21 | B26: Kimia [ SMA ] | C26: 11 | D26: 80 | E26: 3650 | G26: 8000 | H26: 128 | J26: =E26*F26 -> 0 | K26: =G26*I26 -> 0
A27: 22 | B27: Kimia [ SMA ] 1 Tahun | C27: 12 | D27: 128 | E27: 5150 | G27: 8000 | H27: 176 | J27: =E27*F27 -> 0 | K27: =G27*I27 -> 0
A28: 23 | B28: Sejarah [ SMA ] | C28: 10 | D28: 80 | E28: 3650 | G28: 8000 | H28: 112 | J28: =E28*F28 -> 0 | K28: =G28*I28 -> 0
A29: 24 | B29: Sejarah [ SMA ] | C29: 11 | D29: 80 | E29: 3650 | G29: 8000 | H29: 112 | J29: =E29*F29 -> 0 | K29: =G29*I29 -> 0
A30: 25 | B30: Sejarah [ SMA ] 1 Tahun | C30: 12 | D30: 128 | E30: 5150 | G30: 8000 | H30: 192 | J30: =E30*F30 -> 0 | K30: =G30*I30 -> 0
A31: 26 | B31: Sejarah TL [ SMA ] | C31: 11 | D31: 64 | E31: 3350 | G31: 8000 | H31: 112 | J31: =E31*F31 -> 0 | K31: =G31*I31 -> 0
A32: 27 | B32: Sejarah TL [ SMA ] 1 Tahun | C32: 12 | D32: 128 | E32: 5150 | G32: 8000 | H32: 176 | J32: =E32*F32 -> 0 | K32: =G32*I32 -> 0
A33: 28 | B33: Ekonomi [ SMA ] | C33: 10 | D33: 80 | E33: 3650 | G33: 8000 | H33: 112 | J33: =E33*F33 -> 0 | K33: =G33*I33 -> 0
A34: 29 | B34: Ekonomi [ SMA ] | C34: 11 | D34: 80 | E34: 3650 | G34: 8000 | H34: 128 | J34: =E34*F34 -> 0 | K34: =G34*I34 -> 0
A35: 30 | B35: Ekonomi [ SMA ] 1 Tahun | C35: 12 | D35: 128 | E35: 5150 | G35: 8000 | H35: 176 | J35: =E35*F35 -> 0 | K35: =G35*I35 -> 0
... A41: 36 | B41: Sosiologi [ SMA ] 1 Tahun | C41: 12 | D41: 128 | E41: 5150 | G41: 8000 | H41: 176 | J41: =E41*F41 -> 0 | K41: =G41*I41 -> 0
A42: 37 | B42: Antropologi [ SMA ] | C42: 11 | D42: 64 | E42: 3350 | G42: 8000 | J42: =E42*F42 -> 0 | K42: =G42*I42 -> 0
A43: 38 | B43: Antropologi [ SMA ] 1 Tahun | C43: 12 | D43: 128 | E43: 5150 | G43: 8000 | J43: =E43*F43 -> 0 | K43: =G43*I43 -> 0
A44: 39 | B44: Bahasa Inggris [ SMA ] | C44: 10 | D44: 80 | E44: 3650 | G44: 8000 | H44: 112 | J44: =E44*F44 -> 0 | K44: =G44*I44 -> 0
A45: 40 | B45: Bahasa Inggris [ SMA ] | C45: 11 | D45: 80 | E45: 3650 | G45: 8000 | H45: 112 | J45: =E45*F45 -> 0 | K45: =G45*I45 -> 0
A46: 41 | B46: Bahasa Inggris [ SMA ] 1 Tahun | C46: 12 | D46: 128 | E46: 5150 | G46: 8000 | H46: 176 | J46: =E46*F46 -> 0 | K46: =G46*I46 -> 0
...

Sheet SMK
A1: ZAMRUD ESTIMASI SMK
A2: =REKAP!A2 -> Smt. 2 Tahun Ajaran 2026 - 2027
A3: NAMA : | B3: =REKAP!$J$4 -> 0
A4: No | B4: Bidang Studi KUR. MERDEKA | C4: Kode | D4: Kelas | E4: Hal | F4: Harga | G4: ORDER LKS | H4: Harga PG | I4: PG Beli
A6: 1 | B6: Informatika SMK | D6: 10 | E6: 80 | F6: 3650 | H6: 8000 | J6: =F6*G6 -> 0 | K6: =I6*H6 -> 0
A7: 2 | B7: IPAS [SMK] / 1 tahun | D7: 10 | E7: 144 | F7: 5750 | H7: 8000 | J7: =F7*G7 -> 0 | K7: =I7*H7 -> 0
A8: 3 | B8: Sejarah [ SMK ] | D8: 10 | E8: 64 | F8: 3650 | H8: 8000 | J8: =F8*G8 -> 0 | K8: =I8*H8 -> 0
A9: 4 | B9: Sejarah [ SMK ] | D9: 11 | E9: 64 | F9: 3650 | H9: 8000 | J9: =F9*G9 -> 0 | K9: =I9*H9 -> 0
A10: 5 | B10: Sejarah [ SMK ] / 1 tahun | D10: 12 | E10: 128 | F10: 5150 | H10: 8000 | J10: =F10*G10 -> 0 | K10: =I10*H10 -> 0
A11: 6 | B11: Koding SMK | D11: 10 | E11: 64 | F11: 3350 | H11: 8000 | J11: =F11*G11 -> 0 | K11: =I11*H11 -> 0
A12: 7 | B12: Koding SMK | D12: 11 | E12: 64 | F12: 3350 | H12: 8000 | J12: =F12*G12 -> 0
A13: 8 | B13: Koding SMK - 1 tahun | D13: 12 | E13: 128 | F13: 5150 | H13: 8000 | J13: =F13*G13 -> 0
A14: INTENS SMK
A15: 7 | B15: IPAS Rumpun Bisnis | C15: 1 | D15: 10 | E15: 144 | F15: 5750 | H15: 10000 | J15: =F15*G15 -> 0 | K15: =I15*H15 -> 0
A16: 8 | B16: IPAS Rumpun Kesehatan | C16: 2 | D16: 10 | E16: 144 | F16: 5750 | H16: 10000 | J16: =F16*G16 -> 0 | K16: =I16*H16 -> 0
A17: 9 | B17: IPAS Rumpun Teknologi | C17: 3 | D17: 10 | E17: 144 | F17: 5750 | H17: 10000 | J17: =F17*G17 -> 0 | K17: =I17*H17 -> 0
A18: 10 | B18: Akuntansi dan Keuangan Lembaga | C18: 4 | D18: 10 | E18: 144 | F18: 5750 | H18: 10000 | J18: =F18*G18 -> 0 | K18: =I18*H18 -> 0
A19: 11 | B19: Desain Komunikasi Visual | C19: 5 | D19: 10 | E19: 144 | F19: 5750 | H19: 10000 | J19: =F19*G19 -> 0 | K19: =I19*H19 -> 0
A20: 12 | B20: Manajemen Perkantoran dan Layanan Bisnis | C20: 6 | D20: 10 | E20: 144 | F20: 5750 | H20: 10000 | J20: =F20*G20 -> 0 | K20: =I20*H20 -> 0
A21: 13 | B21: Pemasaran | C21: 7 | D21: 10 | E21: 144 | F21: 5750 | H21: 10000 | J21: =F21*G21 -> 0 | K21: =I21*H21 -> 0
A22: 14 | B22: Pengembangan Perangkat Lunak dan Gim | C22: 8 | D22: 10 | E22: 144 | F22: 5750 | H22: 10000 | J22: =F22*G22 -> 0 | K22: =I22*H22 -> 0
A23: 15 | B23: Perhotelan | C23: 9 | D23: 10 | E23: 144 | F23: 5750 | H23: 10000 | J23: =F23*G23 -> 0 | K23: =I23*H23 -> 0
A24: 16 | B24: Seni Rupa | C24: 10 | D24: 10 | E24: 128 | F24: 5150 | H24: 10000 | J24: =F24*G24 -> 0 | K24: =I24*H24 -> 0
A25: 17 | B25: Teknik Jaringan Komputer dan Telekomunikasi | C25: 11 | D25: 10 | E25: 144 | F25: 5750 | H25: 10000 | J25: =F25*G25 -> 0 | K25: =I25*H25 -> 0
A26: 18 | B26: Teknik Mesin | C26: 12 | D26: 10 | E26: 144 | F26: 5750 | H26: 10000 | J26: =F26*G26 -> 0 | K26: =I26*H26 -> 0
A27: 19 | B27: Teknik Otomotif | C27: 13 | D27: 10 | E27: 144 | F27: 5750 | H27: 10000 | J27: =F27*G27 -> 0 | K27: =I27*H27 -> 0
J28: =F28*G28 -> 0 | K28: =I28*H28 -> 0
G29: =SUM(G6:G28) -> 0 | I29: =SUM(I6:I28) -> 0 | J29: =SUM(J6:J28) -> 0 | K29: =SUM(K6:K28) -> 0
G45: =SUM(G6:G44) -> 0 | I45: =SUM(I6:I44) -> 0

Sheet PROD
A1: ZAMRUD PRODUKTIF KURMER
A2: NAMA : | B2: =REKAP!$J$4 -> 0 | H2: MERDEKA
A3: No | D3: Jumlah Halaman | E3: Finishing | F3: Harga | G3: ORDER LKS | H3: Harga PG | I3: PG BELI
A4: 1 | B4: KREATIVITAS, INOVASI, DAN KEWIRAUSAHAAN | D4: 144 | E4: BENDING | F4: 5750 | H4: 10000 | J4: =F4*G4 -> 0 | K4: =H4*I4 -> 0
A5: 2 | B5: 2.1.1 Teknik Pemesinan | C5: Gambar Teknik Manufaktur | D5: 144 | E5: BENDING | F5: 5750 | H5: 10000 | J5: =F5*G5 -> 0 | K5: =H5*I5 -> 0
A6: 3 | C6: Teknik Pemesinan Bubut | D6: 144 | E6: BENDING | F6: 5750 | H6: 10000 | J6: =F6*G6 -> 0 | K6: =H6*I6 -> 0
A7: 4 | C7: Teknik Pemesinan frais | D7: 144 | E7: BENDING | F7: 5750 | H7: 10000 | J7: =F7*G7 -> 0 | K7: =H7*I7 -> 0
A8: 5 | C8: Teknik Pemesinan Gerinda | D8: 144 | E8: BENDING | F8: 5750 | H8: 10000 | J8: =F8*G8 -> 0 | K8: =H8*I8 -> 0
A9: 6 | C9: Teknik Pemesinan Nonkonvensional | D9: 144 | E9: BENDING | F9: 5750 | H9: 10000 | J9: =F9*G9 -> 0 | K9: =H9*I9 -> 0
A10: 7 | B10: 2.1.4 Desain Gambar Mesin | C10: Gambar Teknik Mesin (2024) | E10: BENDING | F10: 5750 | H10: 10000 | J10: =F10*G10 -> 0 | K10: =H10*I10 -> 0
A11: 8 | C11: Pekerjaan Dasar Teknik Mesin (2024) | E11: BENDING | F11: 5750 | H11: 10000 | J11: =F11*G11 -> 0 | K11: =H11*I11 -> 0
A12: 9 | C12: Dasar Perancangan Teknik Mesin (2024) | E12: BENDING | F12: 5750 | H12: 10000 | J12: =F12*G12 -> 0 | K12: =H12*I12 -> 0
A13: 10 | C13: Teknik Gambar Konstruksi | E13: BENDING | F13: 5750 | H13: 10000 | J13: =F13*G13 -> 0 | K13: =H13*I13 -> 0
A14: 11 | C14: Teknik Gambar Produksi | E14: BENDING | F14: 5750 | H14: 10000 | J14: =F14*G14 -> 0 | K14: =H14*I14 -> 0
A15: 12 | C15: Teknik Merancang dengan CAM | E15: BENDING | F15: 5750 | H15: 10000 | J15: =F15*G15 -> 0 | K15: =H15*I15 -> 0
A16: 13 | B16: KREATIVITAS, INOVASI, DAN KEWIRAUSAHAAN | E16: BENDING | F16: 5750 | H16: 10000 | J16: =F16*G16 -> 0 | K16: =H16*I16 -> 0
A17: 14 | B17: 2.2.1 Teknik Kendaraan Ringan | C17: Konversi Energi Kendaraan Ringan | D17: 144 | E17: BENDING | F17: 5750 | H17: 10000 | J17: =F17*G17 -> 0 | K17: =H17*I17 -> 0
A18: 15 | C18: Proses Pelayanan dan Manajemen Bengkel Kendaraan Ringan | D18: 144 | E18: BENDING | F18: 5750 | H18: 10000 | J18: =F18*G18 -> 0 | K18: =H18*I18 -> 0
A19: 16 | C19: Prosedur Penggunaan Kendaraan Ringan | D19: 144 | E19: BENDING | F19: 5750 | H19: 10000 | J19: =F19*G19 -> 0 | K19: =H19*I19 -> 0
A20: 17 | C20: Perawatan Berkala Kendaraan Ringan | D20: 144 | E20: BENDING | F20: 5750 | H20: 10000 | J20: =F20*G20 -> 0 | K20: =H20*I20 -> 0
A21: 18 | C21: Sistem Engine Kendaraan Ringan | D21: 144 | E21: BENDING | F21: 5750 | H21: 10000 | J21: =F21*G21 -> 0 | K21: =H21*I21 -> 0
A22: 19 | C22: Sistem Pemindah Tenaga Kendaraan Ringan | D22: 144 | E22: BENDING | F22: 5750 | H22: 10000 | J22: =F22*G22 -> 0 | K22: =H22*I22 -> 0
A23: 20 | C23: Sistem Sasis Kendaraan Ringan | D23: 144 | E23: BENDING | F23: 5750 | H23: 10000 | J23: =F23*G23 -> 0 | K23: =H23*I23 -> 0
A24: 21 | C24: Sistem Elektrikal Kendaraan Ringan | D24: 144 | E24: BENDING | F24: 5750 | H24: 10000 | J24: =F24*G24 -> 0 | K24: =H24*I24 -> 0
A25: 22 | C25: Sistem Pengaman dan Sistem Kontrol Elektronik Kendaraan Ringan (2024) | D25: 144 | E25: BENDING | F25: 5750 | H25: 10000 | J25: =F25*G25 -> 0 | K25: =H25*I25 -> 0
A26: 23 | B26: 2.2.2 Teknik Sepeda Motor | C26: Perawatan dan Perbaikan Engine Sepeda Motor | D26: 144 | E26: BENDING | F26: 5750 | H26: 10000 | J26: =F26*G26 -> 0 | K26: =H26*I26 -> 0
A27: 24 | C27: Perawatan dan Perbaikan Sasis Sepeda Motor | D27: 144 | E27: BENDING | F27: 5750 | H27: 10000 | J27: =F27*G27 -> 0 | K27: =H27*I27 -> 0
A28: 25 | C28: Perawatan dan Perbaikan Sistem Pemindah Tenaga Sepeda Motor | D28: 144 | E28: BENDING | F28: 5750 | H28: 10000 | J28: =F28*G28 -> 0 | K28: =H28*I28 -> 0
A29: 26 | C29: Perawatan dan Perbaikan Sistem Kelistrikan Sepeda Motor | D29: 144 | E29: BENDING | F29: 5150 | H29: 10000 | J29: =F29*G29 -> 0 | K29: =H29*I29 -> 0
A30: 27 | C30: Perawatan dan Perbaikan Sepeda Motor Listrik dan Hybrid | D30: 144 | E30: BENDING | F30: 5150 | H30: 10000 | J30: =F30*G30 -> 0 | K30: =H30*I30 -> 0
A31: 28 | C31: Perawatan dan Perbaikan Engine Management System Sepeda Motor | D31: 144 | E31: BENDING | F31: 5150 | H31: 10000 | J31: =F31*G31 -> 0 | K31: =H31*I31 -> 0
A32: 29 | C32: Pengelolaan Bengkel Sepeda Motor | D32: 144 | E32: BENDING | F32: 5150 | H32: 10000 | J32: =F32*G32 -> 0 | K32: =H32*I32 -> 0
A33: 30 | B33: KREATIVITAS, INOVASI, DAN KEWIRAUSAHAAN | D33: 128 | E33: BENDING | F33: 5150 | H33: 10000 | J33: =F33*G33 -> 0 | K33: =H33*I33 -> 0
A34: 31 | B34: 4.1.1 Rekayasa Perangkat Lunak | C34: Basis Data | D34: 144 | E34: BENDING | F34: 4850 | H34: 10000 | J34: =F34*G34 -> 0 | K34: =H34*I34 -> 0
A35: 32 | C35: Pemrograman Berbasis Teks, Grafis, dan Multimedia | D35: 144 | E35: BENDING | F35: 4850 | H35: 10000 | J35: =F35*G35 -> 0 | K35: =H35*I35 -> 0
A36: 33 | C36: Pemrograman Web | D36: 144 | E36: BENDING | F36: 4850 | H36: 10000 | J36: =F36*G36 -> 0 | K36: =H36*I36 -> 0
A37: 34 | C37: Pemrograman Perangkat Bergerak | D37: 144 | E37: BENDING | F37: 4850 | H37: 10000 | J37: =F37*G37 -> 0 | K37: =H37*I37 -> 0
A38: 35 | B38: KREATIVITAS, INOVASI, DAN KEWIRAUSAHAAN | D38: 128 | E38: BENDING | F38: 4850 | H38: 10000 | J38: =F38*G38 -> 0 | K38: =H38*I38 -> 0
A39: 36 | B39: 4.2.1 Teknik Komputer dan Jaringan | C39: Perencanaan dan Pengalamatan Jaringan | D39: 128 | E39: BENDING | F39: 4850 | H39: 10000 | J39: =F39*G39 -> 0 | K39: =H39*I39 -> 0
A40: 37 | C40: Teknologi Jaringan Kabel dan Nirkabel | D40: 128 | E40: BENDING | F40: 4850 | H40: 10000 | J40: =F40*G40 -> 0 | K40: =H40*I40 -> 0
...

Sheet MADRASAH
A1: DAFTAR ESTIMASI ZAMRUD MADRASAH
A2: =REKAP!A2 -> Smt. 2 Tahun Ajaran 2026 - 2027 | G2: MERDEKA
A3: NAMA : | B3: =REKAP!$J$4 -> 0
A4: No | B4: BIDANG STUDY KUR 13 | C4: Kls | D4: TINGKAT | E4: Hal | F4: Harga | G4: ORDER LKS | H4: Harga PG | I4: Hal PG | J4: PG Beli
A6: 1 | B6: Fajar (MI Terpadu) | C6: 1 | D6: MI | E6: 112 | F6: 4350 | H6: 9000 | K6: =G6*F6 -> 0 | L6: =J6*H6 -> 0
A7: 2 | B7: Fajar (MI Terpadu) | C7: 2 | D7: MI | E7: 112 | F7: 4350 | H7: 9000 | K7: =G7*F7 -> 0 | L7: =J7*H7 -> 0
A8: 3 | B8: Fajar (MI Terpadu) | C8: 3 | D8: MI | E8: 112 | F8: 4350 | H8: 9000 | K8: =G8*F8 -> 0 | L8: =J8*H8 -> 0
A9: 4 | B9: Fajar (MI Terpadu) | C9: 4 | D9: MI | E9: 112 | F9: 4350 | H9: 9000 | K9: =G9*F9 -> 0 | L9: =J9*H9 -> 0
A10: 5 | B10: Fajar (MI Terpadu) | C10: 5 | D10: MI | E10: 112 | F10: 4350 | H10: 9000 | K10: =G10*F10 -> 0 | L10: =J10*H10 -> 0
A11: 6 | B11: Fajar (MI Terpadu) | C11: 6 | D11: MI | E11: 112 | F11: 4350 | H11: 9000 | K11: =G11*F11 -> 0 | L11: =J11*H11 -> 0
A12: 7 | B12: Alquran Hadis | C12: 1 | D12: MI | E12: 64 | F12: 3350 | H12: 8000 | I12: 80 | K12: =G12*F12 -> 0 | L12: =J12*H12 -> 0
A13: 8 | B13: Alquran Hadis | C13: 2 | D13: MI | E13: 64 | F13: 3350 | H13: 8000 | I13: 80 | K13: =G13*F13 -> 0 | L13: =J13*H13 -> 0
A14: 9 | B14: Alquran Hadis | C14: 3 | D14: MI | E14: 64 | F14: 3350 | H14: 8000 | I14: 96 | K14: =G14*F14 -> 0 | L14: =J14*H14 -> 0
A15: 10 | B15: Alquran Hadis | C15: 4 | D15: MI | E15: 64 | F15: 3350 | H15: 8000 | I15: 96 | K15: =G15*F15 -> 0 | L15: =J15*H15 -> 0
A16: 11 | B16: Alquran Hadis | C16: 5 | D16: MI | E16: 64 | F16: 3350 | H16: 8000 | I16: 80 | K16: =G16*F16 -> 0 | L16: =J16*H16 -> 0
A17: 12 | B17: Alquran Hadis | C17: 6 | D17: MI | E17: 64 | F17: 3350 | H17: 8000 | I17: 96 | K17: =G17*F17 -> 0 | L17: =J17*H17 -> 0
A18: 13 | B18: Fikih | C18: 1 | D18: MI | E18: 64 | F18: 3350 | H18: 8000 | I18: 80 | K18: =G18*F18 -> 0 | L18: =J18*H18 -> 0
A19: 14 | B19: Fikih | C19: 2 | D19: MI | E19: 64 | F19: 3350 | H19: 8000 | I19: 80 | K19: =G19*F19 -> 0 | L19: =J19*H19 -> 0
A20: 15 | B20: Fikih | C20: 3 | D20: MI | E20: 64 | F20: 3350 | H20: 8000 | I20: 80 | K20: =G20*F20 -> 0 | L20: =J20*H20 -> 0
A21: 16 | B21: Fikih | C21: 4 | D21: MI | E21: 64 | F21: 3350 | H21: 8000 | I21: 80 | K21: =G21*F21 -> 0 | L21: =J21*H21 -> 0
A22: 17 | B22: Fikih | C22: 5 | D22: MI | E22: 64 | F22: 3350 | H22: 8000 | I22: 96 | K22: =G22*F22 -> 0 | L22: =J22*H22 -> 0
A23: 18 | B23: Fikih | C23: 6 | D23: MI | E23: 64 | F23: 3350 | H23: 8000 | I23: 80 | K23: =G23*F23 -> 0 | L23: =J23*H23 -> 0
... A69: 64 | B69: Bahasa Arab | C69: 12 | D69: MA | E69: 64 | F69: 3350 | H69: 8000 | I69: 96 | K69: =G69*F69 -> 0 | L69: =J69*H69 -> 0
G70: =SUM(G6:G69) -> 0 | J70: =SUM(J6:J69) -> 0 | K70: =SUM(K6:K69) -> 0 | L70: =SUM(L6:L69) -> 0

Sheet TKA
A1: DAFTAR BUKU TES KEMAMPUAN AKADEMIS ZAMRUD
A2: =REKAP!A2 -> Smt. 2 Tahun Ajaran 2026 - 2027
A3: NAMA : | B3: =REKAP!$J$4 -> 0
A4: No | B4: Tingkat | C4: Bidang | D4: Kls | E4: Hal | F4: Harga | G4: ORDER | H4: Harga PG | I4: PG BELI
A5: 1 | B5: SD/MI | C5: TKA SD TERPADU | D5: 6 | E5: 160 | F5: 7000 | H5: 15000 | J5: =F5*G5 -> 0 | K5: =I5*H5 -> 0
A6: 2 | C6: TKA SD Bahasa Indonesia | D6: 6 | E6: 128 | F6: 6000 | H6: 10000 | J6: =F6*G6 -> 0 | K6: =I6*H6 -> 0
A7: 3 | C7: TKA SD Matematika | D7: 6 | E7: 128 | F7: 6000 | H7: 10000 | J7: =F7*G7 -> 0 | K7: =I7*H7 -> 0
A8: 4 | B8: SMP/MTS | C8: TKA SMP Bahasa Indonesia | D8: 9 | E8: 144 | F8: 6600 | H8: 10000 | J8: =F8*G8 -> 0 | K8: =I8*H8 -> 0
A9: 5 | C9: TKA SMP Matematika | D9: 9 | E9: 144 | F9: 6600 | H9: 10000 | J9: =F9*G9 -> 0 | K9: =I9*H9 -> 0
A10: 6 | B10: SMA-SMK/MA | C10: TKA SMA Pendidikan Pancasila | D10: 12 | E10: 144 | F10: 6600 | H10: 10000 | J10: =F10*G10 -> 0 | K10: =I10*H10 -> 0
A11: 7 | C11: TKA SMA Bahasa Indonesia | D11: 12 | E11: 144 | F11: 6600 | H11: 10000 | J11: =F11*G11 -> 0 | K11: =I11*H11 -> 0
A12: 8 | C12: TKA SMA Bahasa Indonesia Tingkat Lanjut | D12: 12 | E12: 144 | F12: 6600 | H12: 10000 | J12: =F12*G12 -> 0 | K12: =I12*H12 -> 0
A13: 9 | C13: TKA SMA Matematika | D13: 12 | E13: 144 | F13: 6600 | H13: 10000 | J13: =F13*G13 -> 0 | K13: =I13*H13 -> 0
A14: 10 | C14: TKA SMA Matematika Tingkat Lanjut | D14: 12 | E14: 144 | F14: 6600 | H14: 10000 | J14: =F14*G14 -> 0 | K14: =I14*H14 -> 0
A15: 11 | C15: TKA SMA Fisika | D15: 12 | E15: 144 | F15: 6600 | H15: 10000 | J15: =F15*G15 -> 0 | K15: =I15*H15 -> 0
A16: 12 | C16: TKA SMA Biologi | D16: 12 | E16: 144 | F16: 6600 | H16: 10000 | J16: =F16*G16 -> 0 | K16: =I16*H16 -> 0
A17: 13 | C17: TKA SMA Kimia | D17: 12 | E17: 144 | F17: 6600 | H17: 10000 | J17: =F17*G17 -> 0 | K17: =I17*H17 -> 0
A18: 14 | C18: TKA SMA Sejarah | D18: 12 | E18: 144 | F18: 6600 | H18: 10000 | J18: =F18*G18 -> 0 | K18: =I18*H18 -> 0
A19: 15 | C19: TKA SMA Ekonomi | D19: 12 | E19: 144 | F19: 6600 | H19: 10000 | J19: =F19*G19 -> 0 | K19: =I19*H19 -> 0
A20: 16 | C20: TKA SMA Geografi | D20: 12 | E20: 144 | F20: 6600 | H20: 10000 | J20: =F20*G20 -> 0 | K20: =I20*H20 -> 0
A21: 17 | C21: TKA SMA Sosiologi | D21: 12 | E21: 144 | F21: 6600 | H21: 10000 | J21: =F21*G21 -> 0 | K21: =I21*H21 -> 0
A22: 18 | C22: TKA SMA Baha Inggris | D22: 12 | E22: 144 | F22: 6600 | H22: 10000 | J22: =F22*G22 -> 0 | K22: =I22*H22 -> 0
... A24: 20 | C24: TKA SMK/MAK Produk/Projek Kreatif dan Kewirausahaan | D24: 12 | E24: 144 | F24: 6600 | H24: 10000 | J24: =F24*G24 -> 0 | K24: =I24*H24 -> 0
G25: =SUM(G5:G24) -> 0 | I25: =SUM(I5:I24) -> 0 | J25: =SUM(J5:J24) -> 0 | K25: =SUM(K5:K24) -> 0

Sheet ASAJ UM
A1: DAFTAR BUKU ASAJ & UM ZAMRUD
A2: =REKAP!A2 -> Smt. 2 Tahun Ajaran 2026 - 2027
A4: No | B4: Bidang Studi | C4: Kls | D4: Hal | E4: Harga Satuan | F4: ORDER | G4: Harga PG | H4: PG BELI
A5: 1 | B5: SD Terpadu - ASAJ SD | C5: 6 | D5: 272 | E5: 11300 | G5: 18000 | I5: =E5*F5 -> 0 | J5: =G5*H5 -> 0
A6: 2 | B6: Pendidikan Agama Islam dan Budi Pekerti - ASAJ SD | C6: 6 | D6: 112 | E6: 5250 | G6: 10500 | I6: =E6*F6 -> 0 | J6: =G6*H6 -> 0
A7: 3 | B7: PPKn - ASAJ SMP | C7: 9 | D7: 144 | E7: 6600 | G7: 10500 | I7: =E7*F7 -> 0 | J7: =G7*H7 -> 0
A8: 4 | B8: Bahasa Indonesia - ASAJ SMP | C8: 9 | D8: 144 | E8: 6600 | G8: 10500 | I8: =E8*F8 -> 0 | J8: =G8*H8 -> 0
A9: 5 | B9: Matematika - ASAJ SMP | C9: 9 | D9: 144 | E9: 6600 | G9: 10500 | I9: =E9*F9 -> 0 | J9: =G9*H9 -> 0
A10: 6 | B10: IPA - ASAJ SMP | C10: 9 | D10: 144 | E10: 6600 | G10: 10500 | I10: =E10*F10 -> 0 | J10: =G10*H10 -> 0
A11: 7 | B11: IPS - ASAJ SMP | C11: 9 | D11: 144 | E11: 6600 | G11: 10500 | I11: =E11*F11 -> 0 | J11: =G11*H11 -> 0
A12: 8 | B12: Bahasa Inggris - ASAJ SMP | C12: 9 | D12: 144 | E12: 6600 | G12: 10500 | I12: =E12*F12 -> 0 | J12: =G12*H12 -> 0
A13: 9 | B13: Pendidikan Agama Islam dan Budi Pekerti - ASAJ SMP | C13: 9 | D13: 144 | E13: 6600 | G13: 10500 | I13: =E13*F13 -> 0 | J13: =G13*H13 -> 0
A14: 10 | B14: Pendidikan Pancasila SMA/SMK - ASAJ | C14: 12 | D14: 144 | E14: 6600 | G14: 10500 | I14: =E14*F14 -> 0 | J14: =G14*H14 -> 0
A15: 11 | B15: Bahasa Indonesia SMA/SMK - ASAJ | C15: 12 | D15: 144 | E15: 6600 | G15: 10500 | I15: =E15*F15 -> 0 | J15: =G15*H15 -> 0
A16: 12 | B16: Matematika SMA/SMK - ASAJ | C16: 12 | D16: 144 | E16: 6600 | G16: 10500 | I16: =E16*F16 -> 0 | J16: =G16*H16 -> 0
... A38: 34 | B38: Bahasa Arab - UJIAN MADRASAH | C38: 12 | D38: 112 | E38: 5250 | G38: 10500 | I38: =E38*F38 -> 0 | J38: =G38*H38 -> 0
F39: =SUM(F5:F38) -> 0 | H39: =SUM(H5:H38) -> 0 | I39: =SUM(I5:I38) -> 0 | J39: =SUM(J5:J38) -> 0

Sheet jurnal & tk
A1: DAFTAR ESTIMASI ZAMRUD SD MERDEKA
A2: =REKAP!A2 -> Smt. 2 Tahun Ajaran 2026 - 2027
A3: NAMA : | B3: =REKAP!$J$4 -> 0
A4: No | B4: Bidang Studi Kur. Merdeka | C4: Kls | D4: Hal | E4: Harga | F4: ORDER LKS
A6: 1 | B6: Jurnal 7 Kebiasaan Anak Hebat Indonesia | C6: UMUM | D6: 56 | E6: 5500 | G6: =E6*F6 -> 0
A7: 2 | B7: Sekolahku - SMT. 1 | C7: TK A | D7: 32 | E7: 3700 | G7: =E7*F7 -> 0
A8: 3 | B8: Kasihku untuk Ayah dan Ibu - SMT. 1 | C8: TK A | D8: 32 | E8: 3700 | G8: =E8*F8 -> 0
A9: 4 | B9: Aku Cinta Lingkungan - SMT. 1 | C9: TK A | D9: 32 | E9: 3700 | G9: =E9*F9 -> 0
A10: 5 | B10: Aku Anak Indonesia - SMT. 2 | C10: TK A | D10: 32 | E10: 3700 | G10: =E10*F10 -> 0
A11: 6 | B11: Aku Bisa Jaga Diri - SMT. 2 | C11: TK A | D11: 32 | E11: 3700 | G11: =E11*F11 -> 0
A12: 7 | B12: Liburanku Seru! - SMT. 2 | C12: TK A | D12: 32 | E12: 3700 | G12: =E12*F12 -> 0
A13: 8 | B13: Fisik Motorik - TK A | C13: TK A | D13: 32 | E13: 3700 | G13: =E13*F13 -> 0
A14: 9 | B14: Calistung - TK A | C14: TK A | D14: 32 | E14: 3700 | G14: =E14*F14 -> 0
A15: 10 | B15: Baca Tulis Al-Qur'an - TK A | C15: TK A | D15: 32 | E15: 3700 | G15: =E15*F15 -> 0
A16: 11 | B16: Mengenal Huruf Hijaiyah - TK A | C16: TK A | D16: 32 | E16: 3700 | G16: =E16*F16 -> 0
A17: 12 | B17: Belajar di Sekolah - SMT. 1 | C17: TK B | D17: 32 | E17: 3700 | G17: =E17*F17 -> 0
... A26: 21 | B26: Mengenal Huruf Hijaiyah - TK B | C26: TK B | D26: 32 | E26: 3700 | G26: =E26*F26 -> 0
F27: =SUM(F6:F26) -> 0 | G27: =SUM(G6:G26) -> 0

Sheet Base
A1: ESTIMASI SMT 2 Th 2026-2027 | D1: TIDAK UNTUK DIISI | N1: 14 | O1: 15 | P1: 16 | Q1: 17 | R1: 18 | S1: 19 | T1: 20 | U1: 21 | V1: 22 | W1: 23 | X1: 24 | Y1: 25 | Z1: 26 | AA1: 27 | AB1: 28 | AC1: 29 | AD1: 30 | AE1: 31 | AF1: 32 | AG1: 33 | AH1: 34 | AI1: 35 | AJ1: 36 | AK1: 37 | AL1: 38 | AM1: 39 | AN1: 40 | AO1: 41 | AP1: 42 | AQ1: 43 | AR1: 44 | AS1: 45 | AT1: 46 | AU1: 47 | AV1: 48 | AW1: 49 | AX1: 50 | AY1: 51 | AZ1: 52 | BA1: 53 | BB1: 54 | BC1: 55 | BD1: 56 | BE1: 57 | BF1: 58 | BG1: 59 | BH1: 60 | BI1: 61 | BJ1: 62 | BK1: 63 | BL1: 64 | BM1: 65 | BN1: 66 | BO1: 67 | BP1: 68 | BQ1: 69 | BR1: 70 | BS1: 71 | BT1: 72 | BU1: 73 | BV1: 74 | BW1: 75 | BX1: 76 | BY1: 77 | BZ1: 78 | CA1: 79 | CB1: 80 | CC1: 81 | CD1: 82 | CE1: 83 | CF1: 84 | CG1: 85 | CH1: 86 | CI1: 87 | CJ1: 88 | CK1: 89 | CL1: 90 | CM1: 91 | CN1: 92 | CO1: 93 | CP1: 94 | CQ1: 95 | CR1: 96 | CS1: 97 | CT1: 98 | CU1: 99 | CV1: 100 | CW1: 101 | CX1: 102 | CY1: 103 | CZ1: 104 | DA1: 105 | DB1: 106 | DC1: 107 | DD1: 108 | DE1: 109 | DF1: 110 | DG1: 111 | DH1: 112 | DI1: 113 | DJ1: 114 | DK1: 115 | DL1: 116 | DM1: 117 | DN1: 118 | DO1: 119 | DP1: 120 | DQ1: 121 | DR1: 122 | DS1: 123 | DT1: 124 | DU1: 125 | DV1: 126 | DW1: 127 | DX1: 128 | DY1: 129 | DZ1: 130 | EA1: 131 | EB1: 132 | EC1: 133 | ED1: 134 | EE1: 135 | EF1: 136 | EG1: 137 | EH1: 138 | EI1: 139 | EJ1: 140 | EK1: 141 | EL1: 142 | EM1: 143 | EN1: 144 | EO1: 145 | EP1: 146 | EQ1: 147 | ER1: 148 | ES1: 149 | ET1: 150 | EU1: 151 | EV1: 152 | EW1: 153 | EX1: 154 | EY1: 155 | EZ1: 156 | FA1: 157 | FB1: 158 | FC1: 159 | FD1: 160 | FE1: 161 | FF1: 162 | FG1: 163 | FH1: 164 | FI1: 165 | FJ1: 166 | FK1: 167 | FL1: 168 | FM1: 169 | FN1: 170 | FO1: 171 | FP1: 172 | FQ1: 173 | FR1: 174 | FS1: 175 | FT1: 176 | FU1: 177 | FV1: 178 | FW1: 179 | FX1: 180 | FY1: 181 | FZ1: 182 | GA1: 183 | GB1: 184 | GC1: 185 | GD1: 186 | GE1: 187 | GF1: 188 | GG1: 189 | GH1: 190 | GI1: 191 | GJ1: 192 | GK1: 193 | GL1: 194 | GM1: 195 | GN1: 196 | GO1: 197 | GP1: 198 | GQ1: 199 | GR1: 200 | GS1: 201 | GT1: 202 | GU1: 203 | GV1: 204 | GW1: 205 | GX1: 206 | GY1: 207 | GZ1: 208 | HA1: 209 | HB1: 210 | HC1: 211 | HD1: 212 | HE1: 213 | HF1: 214 | HG1: 215 | HH1: 216 | HI1: 217 | HJ1: 218 | HK1: 219 | HL1: 220 | HM1: 221 | HN1: 222 | HO1: 223 | HP1: 224 | HQ1: 225 | HR1: 226 | HS1: 227 | HT1: 228 | HU1: 229 | HV1: 230 | HW1: 231 | HX1: 232 | HY1: 233 | HZ1: 234 | IA1: 235 | IB1: 236 | IC1: 237 | ID1: 238 | IE1: 239 | IF1: 240 | IG1: 241 | IH1: 242 | II1: 243 | IJ1: 244 | IK1: 245 | IL1: 246 | IM1: 247 | IN1: 248 | IO1: 249 | IP1: 250 | IQ1: 251 | IR1: 252 | IS1: 253 | IT1: 254 | IU1: 255 | IV1: 256 | IW1: 257 | IX1: 258 | IY1: 259 | IZ1: 260 | JA1: 261 | JB1: 262 | JC1: 263 | JD1: 264 | JE1: 265 | JF1: 266 | JG1: 267 | JH1: 268 | JI1: 269 | JJ1: 270 | JK1: 271 | JL1: 272 | JM1: 273 | JN1: 274 | JO1: 275 | JP1: 276 | JQ1: 277 | JR1: 278 | JS1: 279 | JT1: 280 | JU1: 281 | JV1: 282 | JW1: 283 | JX1: 284 | JY1: 285 | JZ1: 286 | KA1: 287 | KB1: 288 | KC1: 289 | KD1: 290 | KE1: 291 | KF1: 292 | KG1: 293 | KH1: 294 | KI1: 295 | KJ1: 296 | KK1: 297 | KL1: 298 | KM1: 299 | KN1: 300 | KO1: 301 | KP1: 302 | KQ1: 303 | KR1: 304 | KS1: 305 | KT1: 306 | KU1: 307 | KV1: 308 | KW1: 309 | KX1: 310 | KY1: 311 | KZ1: 312 | LA1: 313 | LB1: 314 | LC1: 315 | LD1: 316 | LE1: 317 | LF1: 318 | LG1: 319 | LH1: 320 | LI1: 321 | LJ1: 322 | LK1: 323 | LL1: 324 | LM1: 325 | LN1: 326 | LO1: 327 | LP1: 328 | LQ1: 329 | LR1: 330 | LS1: 331 | LT1: 332 | LU1: 333 | LV1: 334 | LW1: 335 | LX1: 336 | LY1: 337 | LZ1: 338 | MA1: 339 | MB1: 340 | MC1: 341 | MD1: 342 | ME1: 343 | MF1: 344 | MG1: 345 | MH1: 346 | MO1: 347 | MP1: 348 | MQ1: 349 | MR1: 350 | MS1: 351 | MT1: 352 | MU1: 353 | MV1: 354 | MW1: 355 | MX1: 356 | MY1: 357 | MZ1: 358 | NA1: 359 | NB1: 360 | NC1: 361 | ND1: 362 | NE1: 363 | NF1: 364 | NG1: 365 | NH1: 366 | NI1: 367 | NJ1: 368 | NK1: 369 | NL1: 370 | NM1: 371 | NN1: 372 | NO1: 373 | NP1: 374 | NQ1: 375 | NR1: 376 | NS1: 377 | NT1: 378 | NU1: 379 | NV1: 380 | NW1: 381 | NX1: 382 | NY1: 383 | NZ1: 384 | OA1: 385 | OB1: 386 | OC1: 387 | OD1: 388 | OE1: 389 | OF1: 390 | OG1: 391 | OH1: 392 | OI1: 393 | OJ1: 394 | OK1: 395 | OL1: 396 | OM1: 397 | ON1: 398 | OO1: 399 | OP1: 400 | OQ1: 401 | OR1: 402 | OS1: 403 | OT1: 404 | OU1: 405 | OV1: 406 | OW1: 407 | OX1: 408 | OY1: 409 | OZ1: 410 | PA1: 411 | PB1: 412 | PC1: 413 | PD1: 414 | PE1: 415 | PF1: 416 | PG1: 417 | PH1: 418 | PI1: 419 | PJ1: 420 | PK1: 421 | PL1: 422 | PM1: 423 | PN1: 424 | PO1: 425 | PP1: 426 | PQ1: 427 | PR1: 428 | PS1: 429 | PT1: 430 | PU1: 431 | PV1: 432 | PW1: 433 | PX1: 434 | PY1: 435 | PZ1: 436 | QA1: 437 | QB1: 438 | QC1: 439 | QD1: 440 | QE1: 441 | QF1: 442 | QG1: 443 | QH1: 444 | QM1: 445 | QN1: 450 | QO1: 451 | QP1: 452 | QQ1: 453 | QR1: 454 | QS1: 455 | QT1: 456 | QU1: 457 | QV1: 458 | QW1: 459 | QX1: 460 | QY1: 461 | QZ1: 462 | RA1: 463 | RB1: 464 | RC1: 465 | RD1: 466 | RE1: 467 | RF1: 468 | RG1: 469 | RH1: 470 | RI1: 471 | RJ1: 472 | RK1: 473 | RL1: 474 | RM1: 475 | RN1: 476 | RO1: 477 | RP1: 478 | RQ1: 479 | RR1: 480 | RS1: 481 | RT1: 482 | RU1: 483 | RV1: 484 | RW1: 485 | RX1: 486 | RY1: 487 | RZ1: 488 | SA1: 489 | SB1: 490 | SC1: 491 | SD1: 492 | SE1: 493 | SF1: 494 | SG1: 495 | SH1: 496 | SI1: 497 | SJ1: 498 | SK1: 499 | SL1: 500 | SM1: 501 | SN1: 502 | SO1: 503 | SP1: 504 | SQ1: 505 | SR1: 506 | SS1: 507 | ST1: 508 | SU1: 509 | SV1: 510 | SW1: 511 | SX1: 512 | SY1: 513 | SZ1: 514 | TA1: 515 | TB1: 516 | TC1: 517 | TD1: 518 | TE1: 519 | TF1: 520 | TG1: 521 | TH1: 522 | TI1: 523 | TJ1: 524 | TK1: 525 | TL1: 526 | TM1: 527 | TN1: 528 | TO1: 529 | TP1: 530 | TQ1: 531 | TR1: 532 | TS1: 533 | TT1: 534 | TU1: 535 | TV1: 536 | TW1: 537 | TX1: 538 | TY1: 539 | TZ1: 540 | UA1: 541 | UB1: 542 | UC1: 543 | UD1: 544 | UE1: 545 | UF1: 546 | UG1: 547 | UH1: 548 | UI1: 549 | UJ1: 550 | UK1: 551 | UL1: 552 | UM1: 553 | UN1: 554 | UO1: 555 | UP1: 556 | UQ1: 557 | UR1: 558 | US1: 559 | UT1: 560 | UU1: 561 | UV1: 562 | UW1: 563 | UX1: 564 | UY1: 565 | UZ1: 566 | VA1: 567 | VB1: 568 | VC1: 569 | VD1: 570 | VE1: 571 | VF1: 572 | VG1: 573 | VH1: 574 | VI1: 575 | VJ1: 576 | VK1: 577 | VL1: 578 | VM1: 579 | VN1: 580 | VO1: 581 | VP1: 582 | VQ1: 583 | VR1: 584 | VS1: 585 | VT1: 586 | VU1: 587 | VV1: 588 | VW1: 589 | VX1: 590 | VY1: 591 | VZ1: 592 | WA1: 593 | WB1: 594 | WC1: 595 | WD1: 596 | WE1: 597 | WF1: 598 | WG1: 599 | WH1: 600 | WI1: 601 | WJ1: 602 | WK1: 603 | WL1: 604 | WM1: 605 | WN1: 606 | WO1: 607 | WP1: 608 | WQ1: 609 | WR1: 610 | WS1: 611 | WT1: 612 | WU1: 613 | WV1: 614 | WW1: 615 | WX1: 616 | WY1: 617 | WZ1: 618 | XA1: 619 | XB1: 620 | XC1: 621 | XD1: 622 | XE1: 623 | XF1: 624 | XG1: 625 | XH1: 626 | XI1: 627 | XJ1: 628 | XK1: 629 | XL1: 630 | XM1: 631 | XN1: 632 | XO1: 633 | XP1: 634 | XQ1: 635 | XR1: 636 | XS1: 637 | XT1: 638 | XU1: 639 | XV1: 640 | XW1: 641 | XX1: 642 | XY1: 643 | XZ1: 644 | YA1: 645 | YB1: 646 | YC1: 647 | YD1: 648 | YE1: 649 | YF1: 650 | YG1: 651 | YH1: 652 | YI1: 653 | YJ1: 654 | YK1: 655 | YL1: 656 | YM1: 657 | YN1: 658 | YO1: 659 | YP1: 660 | YQ1: 661 | YR1: 662 | YS1: 663 | YT1: 664 | YU1: 665 | YV1: 666 | YW1: 667 | YX1: 668 | YY1: 669 | YZ1: 670 | ZA1: 671 | ZB1: 672 | ZC1: 673 | ZD1: 674 | ZE1: 675 | ZF1: 676 | ZG1: 677 | ZH1: 678 | ZI1: 679 | ZJ1: 680 | ZK1: 681 | ZL1: 682 | ZM1: 683 | ZN1: 684 | ZO1: 685 | ZP1: 686 | ZQ1: 687 | ZR1: 688 | ZS1: 689 | ZT1: 690 | ZU1: 691 | ZV1: 692 | ZW1: 693 | ZX1: 694 | ZY1: 695 | ZZ1: 696 | AAA1: 697 | AAB1: 698 | AAC1: 699 | AAD1: 700 | AAE1: 701 | AAF1: 702 | AAG1: 703 | AAH1: 704 | AAI1: 705 | AAJ1: 706 | AAK1: 707 | AAL1: 708 | AAM1: 709 | AAN1: 710 | AAO1: 711 | AAP1: 712 | AAQ1: 713 | AAR1: 714 | AAS1: 715 | AAT1: 716 | AAU1: 717 | AAV1: 718 | AAW1: 719 | AAX1: 720 | AAY1: 721 | AAZ1: 722 | ABA1: 723 | ABB1: 724 | ABC1: 725 | ABD1: 726 | ABE1: 727 | ABF1: 728 | ABG1: 729 | ABH1: 730 | ABI1: 731 | ABJ1: 732 | ABK1: 733 | ABL1: 734 | ACA1: 735 | ACB1: 736 | ACI1: 737
N2: SD TERPADU LAMA | T2: SD MERDEKA | CJ2: SMP MERDEKA | EF2: SMA MERDEKA | GW2: SMK MERDEKA | HB2: Fajar (MI Terpadu) | HH2: HIKMAH | IJ2: FATTAH | IY2: FITRAH | JN2: BAJATIM | JZ2: Prima SD | KZ2: PRIMA SMP | LR2: PRIMA SMA | MN2: PRIMA SMK | MQ2: Intens SMA | NH2: INTENS SMK | NU2: Produktif Lama | QO2: AKM | QR2: AKMI | QU2: P5 SD | RA2: P5 SMP | RD2: P5 SMA | RG2: Jurnal | RH2: TK | SB2: TKA SD | SE2: TKA SMP | SG2: TKA SMA | SV2: US SD | SX2: US SMP | TE2: US SMA | TS2: UM MI | TT2: UMMTS | TY2: UM MA | UD2: Produkti Baru
